Nonebinary[ERROR] - ['Traceback (most recent call last):\n', '  File "auto_run.py", line 40, in _inner\n    fn(*args)\n', '  File "auto_run.py", line 53, in run\n    return contador.read()\n', '  File "/home/somnium/Desktop/CODE/Projects/CV/contador/scrapper/contador.py", line 264, in read\n    users = storage("users")\n', '  File "/home/somnium/Desktop/CODE/Projects/CV/contador/scrapper/contador.py", line 119, in storage\n    with open(db[type_], "r") as f:\n', "FileNotFoundError: [Errno 2] No such file or directory: 'users.json'\n"]
[ERROR] - ['Traceback (most recent call last):\n', '  File "/home/somnium/Desktop/CODE/Projects/CV/contador/venv/lib/python3.8/site-packages/urllib3/connectionpool.py", line 670, in urlopen\n    httplib_response = self._make_request(\n', '  File "/home/somnium/Desktop/CODE/Projects/CV/contador/venv/lib/python3.8/site-packages/urllib3/connectionpool.py", line 426, in _make_request\n    six.raise_from(e, None)\n', '  File "<string>", line 3, in raise_from\n', '  File "/home/somnium/Desktop/CODE/Projects/CV/contador/venv/lib/python3.8/site-packages/urllib3/connectionpool.py", line 421, in _make_request\n    httplib_response = conn.getresponse()\n', '  File "/usr/lib/python3.8/http/client.py", line 1322, in getresponse\n    response.begin()\n', '  File "/usr/lib/python3.8/http/client.py", line 303, in begin\n    version, status, reason = self._read_status()\n', '  File "/usr/lib/python3.8/http/client.py", line 272, in _read_status\n    raise RemoteDisconnected("Remote end closed connection without"\n', 'http.client.RemoteDisconnected: Remote end closed connection without response\n', '\nDuring handling of the above exception, another exception occurred:\n\n', 'Traceback (most recent call last):\n', '  File "auto_run.py", line 40, in _inner\n    fn(*args)\n', '  File "auto_run.py", line 53, in run\n    return contador.read()\n', '  File "/home/somnium/Desktop/CODE/Projects/CV/contador/scrapper/contador.py", line 266, in read\n    succeed, values = _get_reading(user)\n', '  File "/home/somnium/Desktop/CODE/Projects/CV/contador/scrapper/contador.py", line 238, in _get_reading\n    driver = browser_setup()\n', '  File "/home/somnium/Desktop/CODE/Projects/CV/contador/scrapper/contador.py", line 148, in browser_setup\n    driver = Firefox(options=opts)\n', '  File "/home/somnium/Desktop/CODE/Projects/CV/contador/venv/lib/python3.8/site-packages/selenium/webdriver/firefox/webdriver.py", line 170, in __init__\n    RemoteWebDriver.__init__(\n', '  File "/home/somnium/Desktop/CODE/Projects/CV/contador/venv/lib/python3.8/site-packages/selenium/webdriver/remote/webdriver.py", line 157, in __init__\n    self.start_session(capabilities, browser_profile)\n', '  File "/home/somnium/Desktop/CODE/Projects/CV/contador/venv/lib/python3.8/site-packages/selenium/webdriver/remote/webdriver.py", line 252, in start_session\n    response = self.execute(Command.NEW_SESSION, parameters)\n', '  File "/home/somnium/Desktop/CODE/Projects/CV/contador/venv/lib/python3.8/site-packages/selenium/webdriver/remote/webdriver.py", line 319, in execute\n    response = self.command_executor.execute(driver_command, params)\n', '  File "/home/somnium/Desktop/CODE/Projects/CV/contador/venv/lib/python3.8/site-packages/selenium/webdriver/remote/remote_connection.py", line 374, in execute\n    return self._request(command_info[0], url, body=data)\n', '  File "/home/somnium/Desktop/CODE/Projects/CV/contador/venv/lib/python3.8/site-packages/selenium/webdriver/remote/remote_connection.py", line 397, in _request\n    resp = self._conn.request(method, url, body=body, headers=headers)\n', '  File "/home/somnium/Desktop/CODE/Projects/CV/contador/venv/lib/python3.8/site-packages/urllib3/request.py", line 79, in request\n    return self.request_encode_body(\n', '  File "/home/somnium/Desktop/CODE/Projects/CV/contador/venv/lib/python3.8/site-packages/urllib3/request.py", line 171, in request_encode_body\n    return self.urlopen(method, url, **extra_kw)\n', '  File "/home/somnium/Desktop/CODE/Projects/CV/contador/venv/lib/python3.8/site-packages/urllib3/poolmanager.py", line 336, in urlopen\n    response = conn.urlopen(method, u.request_uri, **kw)\n', '  File "/home/somnium/Desktop/CODE/Projects/CV/contador/venv/lib/python3.8/site-packages/urllib3/connectionpool.py", line 724, in urlopen\n    retries = retries.increment(\n', '  File "/home/somnium/Desktop/CODE/Projects/CV/contador/venv/lib/python3.8/site-packages/urllib3/util/retry.py", line 403, in increment\n    raise six.reraise(type(error), error, _stacktrace)\n', '  File "/home/somnium/Desktop/CODE/Projects/CV/contador/venv/lib/python3.8/site-packages/urllib3/packages/six.py", line 734, in reraise\n    raise value.with_traceback(tb)\n', '  File "/home/somnium/Desktop/CODE/Projects/CV/contador/venv/lib/python3.8/site-packages/urllib3/connectionpool.py", line 670, in urlopen\n    httplib_response = self._make_request(\n', '  File "/home/somnium/Desktop/CODE/Projects/CV/contador/venv/lib/python3.8/site-packages/urllib3/connectionpool.py", line 426, in _make_request\n    six.raise_from(e, None)\n', '  File "<string>", line 3, in raise_from\n', '  File "/home/somnium/Desktop/CODE/Projects/CV/contador/venv/lib/python3.8/site-packages/urllib3/connectionpool.py", line 421, in _make_request\n    httplib_response = conn.getresponse()\n', '  File "/usr/lib/python3.8/http/client.py", line 1322, in getresponse\n    response.begin()\n', '  File "/usr/lib/python3.8/http/client.py", line 303, in begin\n    version, status, reason = self._read_status()\n', '  File "/usr/lib/python3.8/http/client.py", line 272, in _read_status\n    raise RemoteDisconnected("Remote end closed connection without"\n', "urllib3.exceptions.ProtocolError: ('Connection aborted.', RemoteDisconnected('Remote end closed connection without response'))\n"]
[ERROR] - ['Traceback (most recent call last):\n', '  File "/home/somnium/Desktop/CODE/Projects/CV/contador/scrapper/run.py", line 38, in _inner\n    fn(*args)\n', '  File "/home/somnium/Desktop/CODE/Projects/CV/contador/scrapper/run.py", line 51, in single\n    return contador.read()\n', '  File "/home/somnium/Desktop/CODE/Projects/CV/contador/scrapper/contador.py", line 266, in read\n    succeed, values = _get_reading(user)\n', '  File "/home/somnium/Desktop/CODE/Projects/CV/contador/scrapper/contador.py", line 245, in _get_reading\n    lectura(driver)\n', '  File "/home/somnium/Desktop/CODE/Projects/CV/contador/scrapper/contador.py", line 219, in lectura\n    if _read_succeed(driver):\n', '  File "/home/somnium/Desktop/CODE/Projects/CV/contador/scrapper/contador.py", line 88, in _read_succeed\n    driver.find_element_by_css_selector(".percent")\n', '  File "/home/somnium/Desktop/CODE/Projects/CV/contador/venv/lib/python3.8/site-packages/selenium/webdriver/remote/webdriver.py", line 598, in find_element_by_css_selector\n    return self.find_element(by=By.CSS_SELECTOR, value=css_selector)\n', '  File "/home/somnium/Desktop/CODE/Projects/CV/contador/venv/lib/python3.8/site-packages/selenium/webdriver/remote/webdriver.py", line 976, in find_element\n    return self.execute(Command.FIND_ELEMENT, {\n', '  File "/home/somnium/Desktop/CODE/Projects/CV/contador/venv/lib/python3.8/site-packages/selenium/webdriver/remote/webdriver.py", line 321, in execute\n    self.error_handler.check_response(response)\n', '  File "/home/somnium/Desktop/CODE/Projects/CV/contador/venv/lib/python3.8/site-packages/selenium/webdriver/remote/errorhandler.py", line 242, in check_response\n    raise exception_class(message, screen, stacktrace)\n', 'selenium.common.exceptions.WebDriverException: Message: Failed to decode response from marionette\n\n']
[ERROR] - ['Traceback (most recent call last):\n', '  File "/home/somnium/Desktop/CODE/Projects/CV/contador/scrapper/run.py", line 38, in _inner\n    fn(*args)\n', '  File "/home/somnium/Desktop/CODE/Projects/CV/contador/scrapper/run.py", line 57, in multiple\n    return contador.read_multiple(pool)\n', '  File "/home/somnium/Desktop/CODE/Projects/CV/contador/scrapper/contador.py", line 273, in read_multiple\n    results = pool.map(_get_reading, users)\n', '  File "/usr/lib/python3.8/multiprocessing/pool.py", line 364, in map\n    return self._map_async(func, iterable, mapstar, chunksize).get()\n', '  File "/usr/lib/python3.8/multiprocessing/pool.py", line 768, in get\n    raise self._value\n', '  File "/usr/lib/python3.8/multiprocessing/pool.py", line 125, in worker\n    result = (True, func(*args, **kwds))\n', '  File "/usr/lib/python3.8/multiprocessing/pool.py", line 48, in mapstar\n    return list(map(*args))\n', '  File "/home/somnium/Desktop/CODE/Projects/CV/contador/scrapper/contador.py", line 243, in _get_reading\n    login(driver, username, password)\n', '  File "/home/somnium/Desktop/CODE/Projects/CV/contador/scrapper/contador.py", line 159, in login\n    user_in = driver.find_element_by_name("username")\n', '  File "/home/somnium/Desktop/CODE/Projects/CV/contador/venv/lib/python3.8/site-packages/selenium/webdriver/remote/webdriver.py", line 496, in find_element_by_name\n    return self.find_element(by=By.NAME, value=name)\n', '  File "/home/somnium/Desktop/CODE/Projects/CV/contador/venv/lib/python3.8/site-packages/selenium/webdriver/remote/webdriver.py", line 976, in find_element\n    return self.execute(Command.FIND_ELEMENT, {\n', '  File "/home/somnium/Desktop/CODE/Projects/CV/contador/venv/lib/python3.8/site-packages/selenium/webdriver/remote/webdriver.py", line 321, in execute\n    self.error_handler.check_response(response)\n', '  File "/home/somnium/Desktop/CODE/Projects/CV/contador/venv/lib/python3.8/site-packages/selenium/webdriver/remote/errorhandler.py", line 242, in check_response\n    raise exception_class(message, screen, stacktrace)\n', 'selenium.common.exceptions.NoSuchWindowException: Message: Browsing context has been discarded\n\n']
[ERROR] - ['Traceback (most recent call last):\n', '  File "/home/somnium/Desktop/CODE/Projects/CV/contador/scrapper/run.py", line 38, in _inner\n    fn(*args)\n', '  File "/home/somnium/Desktop/CODE/Projects/CV/contador/scrapper/run.py", line 57, in multiple\n    return contador.read_multiple(pool)\n', '  File "/home/somnium/Desktop/CODE/Projects/CV/contador/scrapper/contador.py", line 273, in read_multiple\n    results = pool.map(_get_reading, users)\n', '  File "/usr/lib/python3.8/multiprocessing/pool.py", line 364, in map\n    return self._map_async(func, iterable, mapstar, chunksize).get()\n', '  File "/usr/lib/python3.8/multiprocessing/pool.py", line 768, in get\n    raise self._value\n', '  File "/usr/lib/python3.8/multiprocessing/pool.py", line 125, in worker\n    result = (True, func(*args, **kwds))\n', '  File "/usr/lib/python3.8/multiprocessing/pool.py", line 48, in mapstar\n    return list(map(*args))\n', '  File "/home/somnium/Desktop/CODE/Projects/CV/contador/scrapper/contador.py", line 240, in _get_reading\n    _wait_to_be_clickable(driver, "li.toggleonopen:nth-child(4)")\n', '  File "/home/somnium/Desktop/CODE/Projects/CV/contador/scrapper/contador.py", line 75, in _wait_to_be_clickable\n    btn = driver.find_element_by_css_selector(selector)\n', '  File "/home/somnium/Desktop/CODE/Projects/CV/contador/venv/lib/python3.8/site-packages/selenium/webdriver/remote/webdriver.py", line 598, in find_element_by_css_selector\n    return self.find_element(by=By.CSS_SELECTOR, value=css_selector)\n', '  File "/home/somnium/Desktop/CODE/Projects/CV/contador/venv/lib/python3.8/site-packages/selenium/webdriver/remote/webdriver.py", line 976, in find_element\n    return self.execute(Command.FIND_ELEMENT, {\n', '  File "/home/somnium/Desktop/CODE/Projects/CV/contador/venv/lib/python3.8/site-packages/selenium/webdriver/remote/webdriver.py", line 321, in execute\n    self.error_handler.check_response(response)\n', '  File "/home/somnium/Desktop/CODE/Projects/CV/contador/venv/lib/python3.8/site-packages/selenium/webdriver/remote/errorhandler.py", line 242, in check_response\n    raise exception_class(message, screen, stacktrace)\n', 'selenium.common.exceptions.NoSuchWindowException: Message: Browsing context has been discarded\n\n']
[ERROR] - ['Traceback (most recent call last):\n', '  File "/home/somnium/Desktop/CODE/Projects/CV/contador/venv/lib/python3.8/site-packages/urllib3/connectionpool.py", line 670, in urlopen\n    httplib_response = self._make_request(\n', '  File "/home/somnium/Desktop/CODE/Projects/CV/contador/venv/lib/python3.8/site-packages/urllib3/connectionpool.py", line 426, in _make_request\n    six.raise_from(e, None)\n', '  File "<string>", line 3, in raise_from\n', '  File "/home/somnium/Desktop/CODE/Projects/CV/contador/venv/lib/python3.8/site-packages/urllib3/connectionpool.py", line 421, in _make_request\n    httplib_response = conn.getresponse()\n', '  File "/usr/lib/python3.8/http/client.py", line 1322, in getresponse\n    response.begin()\n', '  File "/usr/lib/python3.8/http/client.py", line 303, in begin\n    version, status, reason = self._read_status()\n', '  File "/usr/lib/python3.8/http/client.py", line 272, in _read_status\n    raise RemoteDisconnected("Remote end closed connection without"\n', 'http.client.RemoteDisconnected: Remote end closed connection without response\n', '\nDuring handling of the above exception, another exception occurred:\n\n', 'Traceback (most recent call last):\n', '  File "/home/somnium/Desktop/CODE/Projects/CV/contador/scrapper/run.py", line 38, in _inner\n    fn(*args)\n', '  File "/home/somnium/Desktop/CODE/Projects/CV/contador/scrapper/run.py", line 57, in multiple\n    return contador.read_multiple(pool)\n', '  File "/home/somnium/Desktop/CODE/Projects/CV/contador/scrapper/contador.py", line 273, in read_multiple\n    results = pool.map(_get_reading, users)\n', '  File "/usr/lib/python3.8/multiprocessing/pool.py", line 364, in map\n    return self._map_async(func, iterable, mapstar, chunksize).get()\n', '  File "/usr/lib/python3.8/multiprocessing/pool.py", line 768, in get\n    raise self._value\n', '  File "/usr/lib/python3.8/multiprocessing/pool.py", line 125, in worker\n    result = (True, func(*args, **kwds))\n', '  File "/usr/lib/python3.8/multiprocessing/pool.py", line 48, in mapstar\n    return list(map(*args))\n', '  File "/home/somnium/Desktop/CODE/Projects/CV/contador/scrapper/contador.py", line 239, in _get_reading\n    driver.get("https://www.edistribucion.com/es/index.html")\n', '  File "/home/somnium/Desktop/CODE/Projects/CV/contador/venv/lib/python3.8/site-packages/selenium/webdriver/remote/webdriver.py", line 333, in get\n    self.execute(Command.GET, {\'url\': url})\n', '  File "/home/somnium/Desktop/CODE/Projects/CV/contador/venv/lib/python3.8/site-packages/selenium/webdriver/remote/webdriver.py", line 319, in execute\n    response = self.command_executor.execute(driver_command, params)\n', '  File "/home/somnium/Desktop/CODE/Projects/CV/contador/venv/lib/python3.8/site-packages/selenium/webdriver/remote/remote_connection.py", line 374, in execute\n    return self._request(command_info[0], url, body=data)\n', '  File "/home/somnium/Desktop/CODE/Projects/CV/contador/venv/lib/python3.8/site-packages/selenium/webdriver/remote/remote_connection.py", line 397, in _request\n    resp = self._conn.request(method, url, body=body, headers=headers)\n', '  File "/home/somnium/Desktop/CODE/Projects/CV/contador/venv/lib/python3.8/site-packages/urllib3/request.py", line 79, in request\n    return self.request_encode_body(\n', '  File "/home/somnium/Desktop/CODE/Projects/CV/contador/venv/lib/python3.8/site-packages/urllib3/request.py", line 171, in request_encode_body\n    return self.urlopen(method, url, **extra_kw)\n', '  File "/home/somnium/Desktop/CODE/Projects/CV/contador/venv/lib/python3.8/site-packages/urllib3/poolmanager.py", line 336, in urlopen\n    response = conn.urlopen(method, u.request_uri, **kw)\n', '  File "/home/somnium/Desktop/CODE/Projects/CV/contador/venv/lib/python3.8/site-packages/urllib3/connectionpool.py", line 724, in urlopen\n    retries = retries.increment(\n', '  File "/home/somnium/Desktop/CODE/Projects/CV/contador/venv/lib/python3.8/site-packages/urllib3/util/retry.py", line 403, in increment\n    raise six.reraise(type(error), error, _stacktrace)\n', '  File "/home/somnium/Desktop/CODE/Projects/CV/contador/venv/lib/python3.8/site-packages/urllib3/packages/six.py", line 734, in reraise\n    raise value.with_traceback(tb)\n', '  File "/home/somnium/Desktop/CODE/Projects/CV/contador/venv/lib/python3.8/site-packages/urllib3/connectionpool.py", line 670, in urlopen\n    httplib_response = self._make_request(\n', '  File "/home/somnium/Desktop/CODE/Projects/CV/contador/venv/lib/python3.8/site-packages/urllib3/connectionpool.py", line 426, in _make_request\n    six.raise_from(e, None)\n', '  File "<string>", line 3, in raise_from\n', '  File "/home/somnium/Desktop/CODE/Projects/CV/contador/venv/lib/python3.8/site-packages/urllib3/connectionpool.py", line 421, in _make_request\n    httplib_response = conn.getresponse()\n', '  File "/usr/lib/python3.8/http/client.py", line 1322, in getresponse\n    response.begin()\n', '  File "/usr/lib/python3.8/http/client.py", line 303, in begin\n    version, status, reason = self._read_status()\n', '  File "/usr/lib/python3.8/http/client.py", line 272, in _read_status\n    raise RemoteDisconnected("Remote end closed connection without"\n', "urllib3.exceptions.ProtocolError: ('Connection aborted.', RemoteDisconnected('Remote end closed connection without response'))\n"]
[ERROR] - ['Traceback (most recent call last):\n', '  File "/home/somnium/Desktop/CODE/Projects/CV/contador/scrapper/run.py", line 38, in _inner\n    fn(*args)\n', '  File "/home/somnium/Desktop/CODE/Projects/CV/contador/scrapper/run.py", line 57, in multiple\n    return contador.read_multiple(pool)\n', '  File "/home/somnium/Desktop/CODE/Projects/CV/contador/scrapper/contador.py", line 273, in read_multiple\n    results = pool.map(_get_reading, users)\n', '  File "/usr/lib/python3.8/multiprocessing/pool.py", line 364, in map\n    return self._map_async(func, iterable, mapstar, chunksize).get()\n', '  File "/usr/lib/python3.8/multiprocessing/pool.py", line 768, in get\n    raise self._value\n', '  File "/usr/lib/python3.8/multiprocessing/pool.py", line 125, in worker\n    result = (True, func(*args, **kwds))\n', '  File "/usr/lib/python3.8/multiprocessing/pool.py", line 48, in mapstar\n    return list(map(*args))\n', '  File "/home/somnium/Desktop/CODE/Projects/CV/contador/scrapper/contador.py", line 240, in _get_reading\n    _wait_to_be_clickable(driver, "li.toggleonopen:nth-child(4)")\n', '  File "/home/somnium/Desktop/CODE/Projects/CV/contador/scrapper/contador.py", line 75, in _wait_to_be_clickable\n    btn = driver.find_element_by_css_selector(selector)\n', '  File "/home/somnium/Desktop/CODE/Projects/CV/contador/venv/lib/python3.8/site-packages/selenium/webdriver/remote/webdriver.py", line 598, in find_element_by_css_selector\n    return self.find_element(by=By.CSS_SELECTOR, value=css_selector)\n', '  File "/home/somnium/Desktop/CODE/Projects/CV/contador/venv/lib/python3.8/site-packages/selenium/webdriver/remote/webdriver.py", line 976, in find_element\n    return self.execute(Command.FIND_ELEMENT, {\n', '  File "/home/somnium/Desktop/CODE/Projects/CV/contador/venv/lib/python3.8/site-packages/selenium/webdriver/remote/webdriver.py", line 321, in execute\n    self.error_handler.check_response(response)\n', '  File "/home/somnium/Desktop/CODE/Projects/CV/contador/venv/lib/python3.8/site-packages/selenium/webdriver/remote/errorhandler.py", line 242, in check_response\n    raise exception_class(message, screen, stacktrace)\n', 'selenium.common.exceptions.NoSuchWindowException: Message: Browsing context has been discarded\n\n']
[ERROR] - ['Traceback (most recent call last):\n', '  File "/home/somnium/Desktop/CODE/Projects/CV/contador/scrapper/run.py", line 38, in _inner\n    fn(*args)\n', '  File "/home/somnium/Desktop/CODE/Projects/CV/contador/scrapper/run.py", line 57, in multiple\n    return contador.read_multiple(pool)\n', '  File "/home/somnium/Desktop/CODE/Projects/CV/contador/scrapper/contador.py", line 273, in read_multiple\n    results = pool.map(_get_reading, users)\n', '  File "/usr/lib/python3.8/multiprocessing/pool.py", line 364, in map\n    return self._map_async(func, iterable, mapstar, chunksize).get()\n', '  File "/usr/lib/python3.8/multiprocessing/pool.py", line 768, in get\n    raise self._value\n', '  File "/usr/lib/python3.8/multiprocessing/pool.py", line 125, in worker\n    result = (True, func(*args, **kwds))\n', '  File "/usr/lib/python3.8/multiprocessing/pool.py", line 48, in mapstar\n    return list(map(*args))\n', '  File "/home/somnium/Desktop/CODE/Projects/CV/contador/scrapper/contador.py", line 240, in _get_reading\n    _wait_to_be_clickable(driver, "li.toggleonopen:nth-child(4)")\n', '  File "/home/somnium/Desktop/CODE/Projects/CV/contador/scrapper/contador.py", line 75, in _wait_to_be_clickable\n    btn = driver.find_element_by_css_selector(selector)\n', '  File "/home/somnium/Desktop/CODE/Projects/CV/contador/venv/lib/python3.8/site-packages/selenium/webdriver/remote/webdriver.py", line 598, in find_element_by_css_selector\n    return self.find_element(by=By.CSS_SELECTOR, value=css_selector)\n', '  File "/home/somnium/Desktop/CODE/Projects/CV/contador/venv/lib/python3.8/site-packages/selenium/webdriver/remote/webdriver.py", line 976, in find_element\n    return self.execute(Command.FIND_ELEMENT, {\n', '  File "/home/somnium/Desktop/CODE/Projects/CV/contador/venv/lib/python3.8/site-packages/selenium/webdriver/remote/webdriver.py", line 321, in execute\n    self.error_handler.check_response(response)\n', '  File "/home/somnium/Desktop/CODE/Projects/CV/contador/venv/lib/python3.8/site-packages/selenium/webdriver/remote/errorhandler.py", line 242, in check_response\n    raise exception_class(message, screen, stacktrace)\n', 'selenium.common.exceptions.NoSuchWindowException: Message: Browsing context has been discarded\n\n']
[ERROR] - ['Traceback (most recent call last):\n', '  File "/home/somnium/Desktop/CODE/Projects/CV/contador/venv/lib/python3.8/site-packages/urllib3/connectionpool.py", line 670, in urlopen\n    httplib_response = self._make_request(\n', '  File "/home/somnium/Desktop/CODE/Projects/CV/contador/venv/lib/python3.8/site-packages/urllib3/connectionpool.py", line 426, in _make_request\n    six.raise_from(e, None)\n', '  File "<string>", line 3, in raise_from\n', '  File "/home/somnium/Desktop/CODE/Projects/CV/contador/venv/lib/python3.8/site-packages/urllib3/connectionpool.py", line 421, in _make_request\n    httplib_response = conn.getresponse()\n', '  File "/usr/lib/python3.8/http/client.py", line 1322, in getresponse\n    response.begin()\n', '  File "/usr/lib/python3.8/http/client.py", line 303, in begin\n    version, status, reason = self._read_status()\n', '  File "/usr/lib/python3.8/http/client.py", line 272, in _read_status\n    raise RemoteDisconnected("Remote end closed connection without"\n', 'http.client.RemoteDisconnected: Remote end closed connection without response\n', '\nDuring handling of the above exception, another exception occurred:\n\n', 'Traceback (most recent call last):\n', '  File "/home/somnium/Desktop/CODE/Projects/CV/contador/scrapper/run.py", line 38, in _inner\n    fn(*args)\n', '  File "/home/somnium/Desktop/CODE/Projects/CV/contador/scrapper/run.py", line 57, in multiple\n    return contador.read_multiple(pool)\n', '  File "/home/somnium/Desktop/CODE/Projects/CV/contador/scrapper/contador.py", line 273, in read_multiple\n    results = pool.map(_get_reading, users)\n', '  File "/usr/lib/python3.8/multiprocessing/pool.py", line 364, in map\n    return self._map_async(func, iterable, mapstar, chunksize).get()\n', '  File "/usr/lib/python3.8/multiprocessing/pool.py", line 768, in get\n    raise self._value\n', '  File "/usr/lib/python3.8/multiprocessing/pool.py", line 125, in worker\n    result = (True, func(*args, **kwds))\n', '  File "/usr/lib/python3.8/multiprocessing/pool.py", line 48, in mapstar\n    return list(map(*args))\n', '  File "/home/somnium/Desktop/CODE/Projects/CV/contador/scrapper/contador.py", line 245, in _get_reading\n    lectura(driver)\n', '  File "/home/somnium/Desktop/CODE/Projects/CV/contador/scrapper/contador.py", line 219, in lectura\n    if _read_succeed(driver):\n', '  File "/home/somnium/Desktop/CODE/Projects/CV/contador/scrapper/contador.py", line 95, in _read_succeed\n    error = driver.find_element_by_css_selector("[title=\'ENTENDIDO\']")\n', '  File "/home/somnium/Desktop/CODE/Projects/CV/contador/venv/lib/python3.8/site-packages/selenium/webdriver/remote/webdriver.py", line 598, in find_element_by_css_selector\n    return self.find_element(by=By.CSS_SELECTOR, value=css_selector)\n', '  File "/home/somnium/Desktop/CODE/Projects/CV/contador/venv/lib/python3.8/site-packages/selenium/webdriver/remote/webdriver.py", line 976, in find_element\n    return self.execute(Command.FIND_ELEMENT, {\n', '  File "/home/somnium/Desktop/CODE/Projects/CV/contador/venv/lib/python3.8/site-packages/selenium/webdriver/remote/webdriver.py", line 319, in execute\n    response = self.command_executor.execute(driver_command, params)\n', '  File "/home/somnium/Desktop/CODE/Projects/CV/contador/venv/lib/python3.8/site-packages/selenium/webdriver/remote/remote_connection.py", line 374, in execute\n    return self._request(command_info[0], url, body=data)\n', '  File "/home/somnium/Desktop/CODE/Projects/CV/contador/venv/lib/python3.8/site-packages/selenium/webdriver/remote/remote_connection.py", line 397, in _request\n    resp = self._conn.request(method, url, body=body, headers=headers)\n', '  File "/home/somnium/Desktop/CODE/Projects/CV/contador/venv/lib/python3.8/site-packages/urllib3/request.py", line 79, in request\n    return self.request_encode_body(\n', '  File "/home/somnium/Desktop/CODE/Projects/CV/contador/venv/lib/python3.8/site-packages/urllib3/request.py", line 171, in request_encode_body\n    return self.urlopen(method, url, **extra_kw)\n', '  File "/home/somnium/Desktop/CODE/Projects/CV/contador/venv/lib/python3.8/site-packages/urllib3/poolmanager.py", line 336, in urlopen\n    response = conn.urlopen(method, u.request_uri, **kw)\n', '  File "/home/somnium/Desktop/CODE/Projects/CV/contador/venv/lib/python3.8/site-packages/urllib3/connectionpool.py", line 724, in urlopen\n    retries = retries.increment(\n', '  File "/home/somnium/Desktop/CODE/Projects/CV/contador/venv/lib/python3.8/site-packages/urllib3/util/retry.py", line 403, in increment\n    raise six.reraise(type(error), error, _stacktrace)\n', '  File "/home/somnium/Desktop/CODE/Projects/CV/contador/venv/lib/python3.8/site-packages/urllib3/packages/six.py", line 734, in reraise\n    raise value.with_traceback(tb)\n', '  File "/home/somnium/Desktop/CODE/Projects/CV/contador/venv/lib/python3.8/site-packages/urllib3/connectionpool.py", line 670, in urlopen\n    httplib_response = self._make_request(\n', '  File "/home/somnium/Desktop/CODE/Projects/CV/contador/venv/lib/python3.8/site-packages/urllib3/connectionpool.py", line 426, in _make_request\n    six.raise_from(e, None)\n', '  File "<string>", line 3, in raise_from\n', '  File "/home/somnium/Desktop/CODE/Projects/CV/contador/venv/lib/python3.8/site-packages/urllib3/connectionpool.py", line 421, in _make_request\n    httplib_response = conn.getresponse()\n', '  File "/usr/lib/python3.8/http/client.py", line 1322, in getresponse\n    response.begin()\n', '  File "/usr/lib/python3.8/http/client.py", line 303, in begin\n    version, status, reason = self._read_status()\n', '  File "/usr/lib/python3.8/http/client.py", line 272, in _read_status\n    raise RemoteDisconnected("Remote end closed connection without"\n', "urllib3.exceptions.ProtocolError: ('Connection aborted.', RemoteDisconnected('Remote end closed connection without response'))\n"]
[ERROR] - ['Traceback (most recent call last):\n', '  File "/home/somnium/Desktop/CODE/Projects/CV/contador/venv/lib/python3.8/site-packages/urllib3/connectionpool.py", line 670, in urlopen\n    httplib_response = self._make_request(\n', '  File "/home/somnium/Desktop/CODE/Projects/CV/contador/venv/lib/python3.8/site-packages/urllib3/connectionpool.py", line 426, in _make_request\n    six.raise_from(e, None)\n', '  File "<string>", line 3, in raise_from\n', '  File "/home/somnium/Desktop/CODE/Projects/CV/contador/venv/lib/python3.8/site-packages/urllib3/connectionpool.py", line 421, in _make_request\n    httplib_response = conn.getresponse()\n', '  File "/usr/lib/python3.8/http/client.py", line 1322, in getresponse\n    response.begin()\n', '  File "/usr/lib/python3.8/http/client.py", line 303, in begin\n    version, status, reason = self._read_status()\n', '  File "/usr/lib/python3.8/http/client.py", line 272, in _read_status\n    raise RemoteDisconnected("Remote end closed connection without"\n', 'http.client.RemoteDisconnected: Remote end closed connection without response\n', '\nDuring handling of the above exception, another exception occurred:\n\n', 'Traceback (most recent call last):\n', '  File "/home/somnium/Desktop/CODE/Projects/CV/contador/scrapper/run.py", line 38, in _inner\n    fn(*args)\n', '  File "/home/somnium/Desktop/CODE/Projects/CV/contador/scrapper/run.py", line 57, in multiple\n    return contador.read_multiple(pool)\n', '  File "/home/somnium/Desktop/CODE/Projects/CV/contador/scrapper/contador.py", line 273, in read_multiple\n    results = pool.map(_get_reading, users)\n', '  File "/usr/lib/python3.8/multiprocessing/pool.py", line 364, in map\n    return self._map_async(func, iterable, mapstar, chunksize).get()\n', '  File "/usr/lib/python3.8/multiprocessing/pool.py", line 768, in get\n    raise self._value\n', '  File "/usr/lib/python3.8/multiprocessing/pool.py", line 125, in worker\n    result = (True, func(*args, **kwds))\n', '  File "/usr/lib/python3.8/multiprocessing/pool.py", line 48, in mapstar\n    return list(map(*args))\n', '  File "/home/somnium/Desktop/CODE/Projects/CV/contador/scrapper/contador.py", line 245, in _get_reading\n    lectura(driver)\n', '  File "/home/somnium/Desktop/CODE/Projects/CV/contador/scrapper/contador.py", line 227, in lectura\n    lectura(driver, False)\n', '  File "/home/somnium/Desktop/CODE/Projects/CV/contador/scrapper/contador.py", line 219, in lectura\n    if _read_succeed(driver):\n', '  File "/home/somnium/Desktop/CODE/Projects/CV/contador/scrapper/contador.py", line 95, in _read_succeed\n    error = driver.find_element_by_css_selector("[title=\'ENTENDIDO\']")\n', '  File "/home/somnium/Desktop/CODE/Projects/CV/contador/venv/lib/python3.8/site-packages/selenium/webdriver/remote/webdriver.py", line 598, in find_element_by_css_selector\n    return self.find_element(by=By.CSS_SELECTOR, value=css_selector)\n', '  File "/home/somnium/Desktop/CODE/Projects/CV/contador/venv/lib/python3.8/site-packages/selenium/webdriver/remote/webdriver.py", line 976, in find_element\n    return self.execute(Command.FIND_ELEMENT, {\n', '  File "/home/somnium/Desktop/CODE/Projects/CV/contador/venv/lib/python3.8/site-packages/selenium/webdriver/remote/webdriver.py", line 319, in execute\n    response = self.command_executor.execute(driver_command, params)\n', '  File "/home/somnium/Desktop/CODE/Projects/CV/contador/venv/lib/python3.8/site-packages/selenium/webdriver/remote/remote_connection.py", line 374, in execute\n    return self._request(command_info[0], url, body=data)\n', '  File "/home/somnium/Desktop/CODE/Projects/CV/contador/venv/lib/python3.8/site-packages/selenium/webdriver/remote/remote_connection.py", line 397, in _request\n    resp = self._conn.request(method, url, body=body, headers=headers)\n', '  File "/home/somnium/Desktop/CODE/Projects/CV/contador/venv/lib/python3.8/site-packages/urllib3/request.py", line 79, in request\n    return self.request_encode_body(\n', '  File "/home/somnium/Desktop/CODE/Projects/CV/contador/venv/lib/python3.8/site-packages/urllib3/request.py", line 171, in request_encode_body\n    return self.urlopen(method, url, **extra_kw)\n', '  File "/home/somnium/Desktop/CODE/Projects/CV/contador/venv/lib/python3.8/site-packages/urllib3/poolmanager.py", line 336, in urlopen\n    response = conn.urlopen(method, u.request_uri, **kw)\n', '  File "/home/somnium/Desktop/CODE/Projects/CV/contador/venv/lib/python3.8/site-packages/urllib3/connectionpool.py", line 724, in urlopen\n    retries = retries.increment(\n', '  File "/home/somnium/Desktop/CODE/Projects/CV/contador/venv/lib/python3.8/site-packages/urllib3/util/retry.py", line 403, in increment\n    raise six.reraise(type(error), error, _stacktrace)\n', '  File "/home/somnium/Desktop/CODE/Projects/CV/contador/venv/lib/python3.8/site-packages/urllib3/packages/six.py", line 734, in reraise\n    raise value.with_traceback(tb)\n', '  File "/home/somnium/Desktop/CODE/Projects/CV/contador/venv/lib/python3.8/site-packages/urllib3/connectionpool.py", line 670, in urlopen\n    httplib_response = self._make_request(\n', '  File "/home/somnium/Desktop/CODE/Projects/CV/contador/venv/lib/python3.8/site-packages/urllib3/connectionpool.py", line 426, in _make_request\n    six.raise_from(e, None)\n', '  File "<string>", line 3, in raise_from\n', '  File "/home/somnium/Desktop/CODE/Projects/CV/contador/venv/lib/python3.8/site-packages/urllib3/connectionpool.py", line 421, in _make_request\n    httplib_response = conn.getresponse()\n', '  File "/usr/lib/python3.8/http/client.py", line 1322, in getresponse\n    response.begin()\n', '  File "/usr/lib/python3.8/http/client.py", line 303, in begin\n    version, status, reason = self._read_status()\n', '  File "/usr/lib/python3.8/http/client.py", line 272, in _read_status\n    raise RemoteDisconnected("Remote end closed connection without"\n', "urllib3.exceptions.ProtocolError: ('Connection aborted.', RemoteDisconnected('Remote end closed connection without response'))\n"]
[ERROR] - ['Traceback (most recent call last):\n', '  File "/home/somnium/Desktop/CODE/Projects/CV/contador/venv/lib/python3.8/site-packages/urllib3/connectionpool.py", line 670, in urlopen\n    httplib_response = self._make_request(\n', '  File "/home/somnium/Desktop/CODE/Projects/CV/contador/venv/lib/python3.8/site-packages/urllib3/connectionpool.py", line 426, in _make_request\n    six.raise_from(e, None)\n', '  File "<string>", line 3, in raise_from\n', '  File "/home/somnium/Desktop/CODE/Projects/CV/contador/venv/lib/python3.8/site-packages/urllib3/connectionpool.py", line 421, in _make_request\n    httplib_response = conn.getresponse()\n', '  File "/usr/lib/python3.8/http/client.py", line 1322, in getresponse\n    response.begin()\n', '  File "/usr/lib/python3.8/http/client.py", line 303, in begin\n    version, status, reason = self._read_status()\n', '  File "/usr/lib/python3.8/http/client.py", line 272, in _read_status\n    raise RemoteDisconnected("Remote end closed connection without"\n', 'http.client.RemoteDisconnected: Remote end closed connection without response\n', '\nDuring handling of the above exception, another exception occurred:\n\n', 'Traceback (most recent call last):\n', '  File "/home/somnium/Desktop/CODE/Projects/CV/contador/scrapper/run.py", line 38, in _inner\n    fn(*args)\n', '  File "/home/somnium/Desktop/CODE/Projects/CV/contador/scrapper/run.py", line 57, in multiple\n    return contador.read_multiple(pool)\n', '  File "/home/somnium/Desktop/CODE/Projects/CV/contador/scrapper/contador.py", line 273, in read_multiple\n    results = pool.map(_get_reading, users)\n', '  File "/usr/lib/python3.8/multiprocessing/pool.py", line 364, in map\n    return self._map_async(func, iterable, mapstar, chunksize).get()\n', '  File "/usr/lib/python3.8/multiprocessing/pool.py", line 768, in get\n    raise self._value\n', '  File "/usr/lib/python3.8/multiprocessing/pool.py", line 125, in worker\n    result = (True, func(*args, **kwds))\n', '  File "/usr/lib/python3.8/multiprocessing/pool.py", line 48, in mapstar\n    return list(map(*args))\n', '  File "/home/somnium/Desktop/CODE/Projects/CV/contador/scrapper/contador.py", line 245, in _get_reading\n    lectura(driver)\n', '  File "/home/somnium/Desktop/CODE/Projects/CV/contador/scrapper/contador.py", line 219, in lectura\n    if _read_succeed(driver):\n', '  File "/home/somnium/Desktop/CODE/Projects/CV/contador/scrapper/contador.py", line 88, in _read_succeed\n    driver.find_element_by_css_selector(".percent")\n', '  File "/home/somnium/Desktop/CODE/Projects/CV/contador/venv/lib/python3.8/site-packages/selenium/webdriver/remote/webdriver.py", line 598, in find_element_by_css_selector\n    return self.find_element(by=By.CSS_SELECTOR, value=css_selector)\n', '  File "/home/somnium/Desktop/CODE/Projects/CV/contador/venv/lib/python3.8/site-packages/selenium/webdriver/remote/webdriver.py", line 976, in find_element\n    return self.execute(Command.FIND_ELEMENT, {\n', '  File "/home/somnium/Desktop/CODE/Projects/CV/contador/venv/lib/python3.8/site-packages/selenium/webdriver/remote/webdriver.py", line 319, in execute\n    response = self.command_executor.execute(driver_command, params)\n', '  File "/home/somnium/Desktop/CODE/Projects/CV/contador/venv/lib/python3.8/site-packages/selenium/webdriver/remote/remote_connection.py", line 374, in execute\n    return self._request(command_info[0], url, body=data)\n', '  File "/home/somnium/Desktop/CODE/Projects/CV/contador/venv/lib/python3.8/site-packages/selenium/webdriver/remote/remote_connection.py", line 397, in _request\n    resp = self._conn.request(method, url, body=body, headers=headers)\n', '  File "/home/somnium/Desktop/CODE/Projects/CV/contador/venv/lib/python3.8/site-packages/urllib3/request.py", line 79, in request\n    return self.request_encode_body(\n', '  File "/home/somnium/Desktop/CODE/Projects/CV/contador/venv/lib/python3.8/site-packages/urllib3/request.py", line 171, in request_encode_body\n    return self.urlopen(method, url, **extra_kw)\n', '  File "/home/somnium/Desktop/CODE/Projects/CV/contador/venv/lib/python3.8/site-packages/urllib3/poolmanager.py", line 336, in urlopen\n    response = conn.urlopen(method, u.request_uri, **kw)\n', '  File "/home/somnium/Desktop/CODE/Projects/CV/contador/venv/lib/python3.8/site-packages/urllib3/connectionpool.py", line 724, in urlopen\n    retries = retries.increment(\n', '  File "/home/somnium/Desktop/CODE/Projects/CV/contador/venv/lib/python3.8/site-packages/urllib3/util/retry.py", line 403, in increment\n    raise six.reraise(type(error), error, _stacktrace)\n', '  File "/home/somnium/Desktop/CODE/Projects/CV/contador/venv/lib/python3.8/site-packages/urllib3/packages/six.py", line 734, in reraise\n    raise value.with_traceback(tb)\n', '  File "/home/somnium/Desktop/CODE/Projects/CV/contador/venv/lib/python3.8/site-packages/urllib3/connectionpool.py", line 670, in urlopen\n    httplib_response = self._make_request(\n', '  File "/home/somnium/Desktop/CODE/Projects/CV/contador/venv/lib/python3.8/site-packages/urllib3/connectionpool.py", line 426, in _make_request\n    six.raise_from(e, None)\n', '  File "<string>", line 3, in raise_from\n', '  File "/home/somnium/Desktop/CODE/Projects/CV/contador/venv/lib/python3.8/site-packages/urllib3/connectionpool.py", line 421, in _make_request\n    httplib_response = conn.getresponse()\n', '  File "/usr/lib/python3.8/http/client.py", line 1322, in getresponse\n    response.begin()\n', '  File "/usr/lib/python3.8/http/client.py", line 303, in begin\n    version, status, reason = self._read_status()\n', '  File "/usr/lib/python3.8/http/client.py", line 272, in _read_status\n    raise RemoteDisconnected("Remote end closed connection without"\n', "urllib3.exceptions.ProtocolError: ('Connection aborted.', RemoteDisconnected('Remote end closed connection without response'))\n"]
[ERROR] - ['Traceback (most recent call last):\n', '  File "/home/somnium/Desktop/CODE/Projects/CV/contador/venv/lib/python3.8/site-packages/selenium/webdriver/common/service.py", line 72, in start\n    self.process = subprocess.Popen(cmd, env=self.env,\n', '  File "/usr/lib/python3.8/subprocess.py", line 854, in __init__\n    self._execute_child(args, executable, preexec_fn, close_fds,\n', '  File "/usr/lib/python3.8/subprocess.py", line 1702, in _execute_child\n    raise child_exception_type(errno_num, err_msg, err_filename)\n', "FileNotFoundError: [Errno 2] No such file or directory: './chromedriver'\n", '\nDuring handling of the above exception, another exception occurred:\n\n', 'Traceback (most recent call last):\n', '  File "/home/somnium/Desktop/CODE/Projects/CV/contador/scrapper/run.py", line 38, in _inner\n    fn(*args)\n', '  File "/home/somnium/Desktop/CODE/Projects/CV/contador/scrapper/run.py", line 51, in single\n    return contador.read()\n', '  File "/home/somnium/Desktop/CODE/Projects/CV/contador/scrapper/contador.py", line 281, in read\n    succeed, values = _get_reading(user)\n', '  File "/home/somnium/Desktop/CODE/Projects/CV/contador/scrapper/contador.py", line 253, in _get_reading\n    driver = chrome_browser_setup()\n', '  File "/home/somnium/Desktop/CODE/Projects/CV/contador/scrapper/contador.py", line 163, in chrome_browser_setup\n    driver = Chrome(executable_path="./chromedriver", options=opts)\n', '  File "/home/somnium/Desktop/CODE/Projects/CV/contador/venv/lib/python3.8/site-packages/selenium/webdriver/chrome/webdriver.py", line 73, in __init__\n    self.service.start()\n', '  File "/home/somnium/Desktop/CODE/Projects/CV/contador/venv/lib/python3.8/site-packages/selenium/webdriver/common/service.py", line 81, in start\n    raise WebDriverException(\n', "selenium.common.exceptions.WebDriverException: Message: 'chromedriver' executable needs to be in PATH. Please see https://sites.google.com/a/chromium.org/chromedriver/home\n\n"]
[ERROR] - ['Traceback (most recent call last):\n', '  File "/home/somnium/Desktop/CODE/Projects/CV/contador/scrapper/run.py", line 38, in _inner\n    fn(*args)\n', '  File "/home/somnium/Desktop/CODE/Projects/CV/contador/scrapper/run.py", line 51, in single\n    return contador.read()\n', '  File "/home/somnium/Desktop/CODE/Projects/CV/contador/scrapper/contador.py", line 279, in read\n    succeed, values = _get_reading(user)\n', '  File "/home/somnium/Desktop/CODE/Projects/CV/contador/scrapper/contador.py", line 256, in _get_reading\n    login(driver, username, password)\n', '  File "/home/somnium/Desktop/CODE/Projects/CV/contador/scrapper/contador.py", line 172, in login\n    user_in = driver.find_element_by_name("username")\n', '  File "/home/somnium/Desktop/CODE/Projects/CV/contador/venv/lib/python3.8/site-packages/selenium/webdriver/remote/webdriver.py", line 496, in find_element_by_name\n    return self.find_element(by=By.NAME, value=name)\n', '  File "/home/somnium/Desktop/CODE/Projects/CV/contador/venv/lib/python3.8/site-packages/selenium/webdriver/remote/webdriver.py", line 976, in find_element\n    return self.execute(Command.FIND_ELEMENT, {\n', '  File "/home/somnium/Desktop/CODE/Projects/CV/contador/venv/lib/python3.8/site-packages/selenium/webdriver/remote/webdriver.py", line 321, in execute\n    self.error_handler.check_response(response)\n', '  File "/home/somnium/Desktop/CODE/Projects/CV/contador/venv/lib/python3.8/site-packages/selenium/webdriver/remote/errorhandler.py", line 242, in check_response\n    raise exception_class(message, screen, stacktrace)\n', 'selenium.common.exceptions.NoSuchElementException: Message: no such element: Unable to locate element: {"method":"css selector","selector":"[name="username"]"}\n  (Session info: chrome=83.0.4103.61)\n\n']
[ERROR] - ['Traceback (most recent call last):\n', '  File "/home/somnium/Desktop/CODE/Projects/CV/contador/scrapper/run.py", line 38, in _inner\n    fn(*args)\n', '  File "/home/somnium/Desktop/CODE/Projects/CV/contador/scrapper/run.py", line 51, in single\n    return contador.read()\n', '  File "/home/somnium/Desktop/CODE/Projects/CV/contador/scrapper/contador.py", line 279, in read\n    succeed, values = _get_reading(user)\n', '  File "/home/somnium/Desktop/CODE/Projects/CV/contador/scrapper/contador.py", line 256, in _get_reading\n    login(driver, username, password)\n', '  File "/home/somnium/Desktop/CODE/Projects/CV/contador/scrapper/contador.py", line 172, in login\n    user_in = driver.find_element_by_name("username")\n', '  File "/home/somnium/Desktop/CODE/Projects/CV/contador/venv/lib/python3.8/site-packages/selenium/webdriver/remote/webdriver.py", line 496, in find_element_by_name\n    return self.find_element(by=By.NAME, value=name)\n', '  File "/home/somnium/Desktop/CODE/Projects/CV/contador/venv/lib/python3.8/site-packages/selenium/webdriver/remote/webdriver.py", line 976, in find_element\n    return self.execute(Command.FIND_ELEMENT, {\n', '  File "/home/somnium/Desktop/CODE/Projects/CV/contador/venv/lib/python3.8/site-packages/selenium/webdriver/remote/webdriver.py", line 321, in execute\n    self.error_handler.check_response(response)\n', '  File "/home/somnium/Desktop/CODE/Projects/CV/contador/venv/lib/python3.8/site-packages/selenium/webdriver/remote/errorhandler.py", line 242, in check_response\n    raise exception_class(message, screen, stacktrace)\n', 'selenium.common.exceptions.NoSuchElementException: Message: no such element: Unable to locate element: {"method":"css selector","selector":"[name="username"]"}\n  (Session info: chrome=83.0.4103.61)\n\n']
[ERROR] - ['Traceback (most recent call last):\n', '  File "/home/somnium/Desktop/CODE/Projects/CV/contador/scrapper/run.py", line 38, in _inner\n    fn(*args)\n', '  File "/home/somnium/Desktop/CODE/Projects/CV/contador/scrapper/run.py", line 51, in single\n    return contador.read()\n', '  File "/home/somnium/Desktop/CODE/Projects/CV/contador/scrapper/contador.py", line 281, in read\n    succeed, values = _get_reading(user)\n', '  File "/home/somnium/Desktop/CODE/Projects/CV/contador/scrapper/contador.py", line 253, in _get_reading\n    driver = chrome_browser_setup()\n', '  File "/home/somnium/Desktop/CODE/Projects/CV/contador/scrapper/contador.py", line 160, in chrome_browser_setup\n    options.setBinary("/usr/lib/chromium-browser/chromium-browser");\n', "NameError: name 'options' is not defined\n"]
[ERROR] - ['Traceback (most recent call last):\n', '  File "/home/somnium/Desktop/CODE/Projects/CV/contador/scrapper/run.py", line 38, in _inner\n    fn(*args)\n', '  File "/home/somnium/Desktop/CODE/Projects/CV/contador/scrapper/run.py", line 51, in single\n    return contador.read()\n', '  File "/home/somnium/Desktop/CODE/Projects/CV/contador/scrapper/contador.py", line 281, in read\n    succeed, values = _get_reading(user)\n', '  File "/home/somnium/Desktop/CODE/Projects/CV/contador/scrapper/contador.py", line 253, in _get_reading\n    driver = chrome_browser_setup()\n', '  File "/home/somnium/Desktop/CODE/Projects/CV/contador/scrapper/contador.py", line 160, in chrome_browser_setup\n    opts.setBinary("/usr/lib/chromium-browser/chromium-browser");\n', "AttributeError: 'Options' object has no attribute 'setBinary'\n"]
[ERROR] - ['Traceback (most recent call last):\n', '  File "/home/somnium/Desktop/CODE/Projects/CV/contador/scrapper/run.py", line 38, in _inner\n    fn(*args)\n', '  File "/home/somnium/Desktop/CODE/Projects/CV/contador/scrapper/run.py", line 51, in single\n    return contador.read()\n', '  File "/home/somnium/Desktop/CODE/Projects/CV/contador/scrapper/contador.py", line 281, in read\n    succeed, values = _get_reading(user)\n', '  File "/home/somnium/Desktop/CODE/Projects/CV/contador/scrapper/contador.py", line 253, in _get_reading\n    driver = chrome_browser_setup()\n', '  File "/home/somnium/Desktop/CODE/Projects/CV/contador/scrapper/contador.py", line 160, in chrome_browser_setup\n    opts.binary("/usr/lib/chromium-browser/chromium-browser");\n', "AttributeError: 'Options' object has no attribute 'binary'\n"]
[ERROR] - ['Traceback (most recent call last):\n', '  File "/home/somnium/Desktop/CODE/Projects/CV/contador/scrapper/run.py", line 38, in _inner\n    fn(*args)\n', '  File "/home/somnium/Desktop/CODE/Projects/CV/contador/scrapper/run.py", line 51, in single\n    return contador.read()\n', '  File "/home/somnium/Desktop/CODE/Projects/CV/contador/scrapper/contador.py", line 282, in read\n    succeed, values = _get_reading(user)\n', '  File "/home/somnium/Desktop/CODE/Projects/CV/contador/scrapper/contador.py", line 254, in _get_reading\n    driver = chrome_browser_setup()\n', '  File "/home/somnium/Desktop/CODE/Projects/CV/contador/scrapper/contador.py", line 161, in chrome_browser_setup\n    opts.binary_location("/usr/lib/chromium-browser/chromium-browser");\n', "TypeError: 'str' object is not callable\n"]
[ERROR] - ['Traceback (most recent call last):\n', '  File "/home/somnium/Desktop/CODE/Projects/CV/contador/venv/lib/python3.8/site-packages/selenium/webdriver/common/service.py", line 72, in start\n    self.process = subprocess.Popen(cmd, env=self.env,\n', '  File "/usr/lib/python3.8/subprocess.py", line 854, in __init__\n    self._execute_child(args, executable, preexec_fn, close_fds,\n', '  File "/usr/lib/python3.8/subprocess.py", line 1702, in _execute_child\n    raise child_exception_type(errno_num, err_msg, err_filename)\n', "PermissionError: [Errno 13] Permission denied: '/home/somnium/Desktop/CODE/Projects/CV/contador/scrapper/test_chromedriver'\n", '\nDuring handling of the above exception, another exception occurred:\n\n', 'Traceback (most recent call last):\n', '  File "/home/somnium/Desktop/CODE/Projects/CV/contador/scrapper/run.py", line 38, in _inner\n    fn(*args)\n', '  File "/home/somnium/Desktop/CODE/Projects/CV/contador/scrapper/run.py", line 51, in single\n    return contador.read()\n', '  File "/home/somnium/Desktop/CODE/Projects/CV/contador/scrapper/contador.py", line 282, in read\n    succeed, values = _get_reading(user)\n', '  File "/home/somnium/Desktop/CODE/Projects/CV/contador/scrapper/contador.py", line 254, in _get_reading\n    driver = chrome_browser_setup()\n', '  File "/home/somnium/Desktop/CODE/Projects/CV/contador/scrapper/contador.py", line 163, in chrome_browser_setup\n    driver = Chrome(executable_path=PATH, options=opts)\n', '  File "/home/somnium/Desktop/CODE/Projects/CV/contador/venv/lib/python3.8/site-packages/selenium/webdriver/chrome/webdriver.py", line 73, in __init__\n    self.service.start()\n', '  File "/home/somnium/Desktop/CODE/Projects/CV/contador/venv/lib/python3.8/site-packages/selenium/webdriver/common/service.py", line 86, in start\n    raise WebDriverException(\n', "selenium.common.exceptions.WebDriverException: Message: 'test_chromedriver' executable may have wrong permissions. Please see https://sites.google.com/a/chromium.org/chromedriver/home\n\n"]
[ERROR] - ['Traceback (most recent call last):\n', '  File "/home/somnium/Desktop/CODE/Projects/CV/contador/venv/lib/python3.8/site-packages/selenium/webdriver/common/service.py", line 72, in start\n    self.process = subprocess.Popen(cmd, env=self.env,\n', '  File "/usr/lib/python3.8/subprocess.py", line 854, in __init__\n    self._execute_child(args, executable, preexec_fn, close_fds,\n', '  File "/usr/lib/python3.8/subprocess.py", line 1702, in _execute_child\n    raise child_exception_type(errno_num, err_msg, err_filename)\n', "PermissionError: [Errno 13] Permission denied: '/home/somnium/Desktop/CODE/Projects/CV/contador/scrapper/test_chromedriver'\n", '\nDuring handling of the above exception, another exception occurred:\n\n', 'Traceback (most recent call last):\n', '  File "/home/somnium/Desktop/CODE/Projects/CV/contador/scrapper/run.py", line 38, in _inner\n    fn(*args)\n', '  File "/home/somnium/Desktop/CODE/Projects/CV/contador/scrapper/run.py", line 51, in single\n    return contador.read()\n', '  File "/home/somnium/Desktop/CODE/Projects/CV/contador/scrapper/contador.py", line 282, in read\n    succeed, values = _get_reading(user)\n', '  File "/home/somnium/Desktop/CODE/Projects/CV/contador/scrapper/contador.py", line 254, in _get_reading\n    driver = chrome_browser_setup()\n', '  File "/home/somnium/Desktop/CODE/Projects/CV/contador/scrapper/contador.py", line 163, in chrome_browser_setup\n    driver = Chrome(executable_path=PATH, options=opts)\n', '  File "/home/somnium/Desktop/CODE/Projects/CV/contador/venv/lib/python3.8/site-packages/selenium/webdriver/chrome/webdriver.py", line 73, in __init__\n    self.service.start()\n', '  File "/home/somnium/Desktop/CODE/Projects/CV/contador/venv/lib/python3.8/site-packages/selenium/webdriver/common/service.py", line 86, in start\n    raise WebDriverException(\n', "selenium.common.exceptions.WebDriverException: Message: 'test_chromedriver' executable may have wrong permissions. Please see https://sites.google.com/a/chromium.org/chromedriver/home\n\n"]
[ERROR] - ['Traceback (most recent call last):\n', '  File "/home/somnium/Desktop/CODE/Projects/CV/contador/scrapper/run.py", line 38, in _inner\n    fn(*args)\n', '  File "/home/somnium/Desktop/CODE/Projects/CV/contador/scrapper/run.py", line 51, in single\n    return contador.read()\n', '  File "/home/somnium/Desktop/CODE/Projects/CV/contador/scrapper/contador.py", line 282, in read\n    succeed, values = _get_reading(user)\n', '  File "/home/somnium/Desktop/CODE/Projects/CV/contador/scrapper/contador.py", line 254, in _get_reading\n    driver = chrome_browser_setup()\n', '  File "/home/somnium/Desktop/CODE/Projects/CV/contador/scrapper/contador.py", line 163, in chrome_browser_setup\n    driver = Chrome(executable_path=PATH, options=opts)\n', '  File "/home/somnium/Desktop/CODE/Projects/CV/contador/venv/lib/python3.8/site-packages/selenium/webdriver/chrome/webdriver.py", line 76, in __init__\n    RemoteWebDriver.__init__(\n', '  File "/home/somnium/Desktop/CODE/Projects/CV/contador/venv/lib/python3.8/site-packages/selenium/webdriver/remote/webdriver.py", line 157, in __init__\n    self.start_session(capabilities, browser_profile)\n', '  File "/home/somnium/Desktop/CODE/Projects/CV/contador/venv/lib/python3.8/site-packages/selenium/webdriver/remote/webdriver.py", line 252, in start_session\n    response = self.execute(Command.NEW_SESSION, parameters)\n', '  File "/home/somnium/Desktop/CODE/Projects/CV/contador/venv/lib/python3.8/site-packages/selenium/webdriver/remote/webdriver.py", line 321, in execute\n    self.error_handler.check_response(response)\n', '  File "/home/somnium/Desktop/CODE/Projects/CV/contador/venv/lib/python3.8/site-packages/selenium/webdriver/remote/errorhandler.py", line 242, in check_response\n    raise exception_class(message, screen, stacktrace)\n', 'selenium.common.exceptions.WebDriverException: Message: Unable to either launch or connect to Chrome. Please check that ChromeDriver is up-to-date. Using Chrome binary at: /usr/bin/chromium-browser\n\n']
[ERROR] - ['Traceback (most recent call last):\n', '  File "/home/somnium/Desktop/CODE/Projects/CV/contador/scrapper/run.py", line 38, in _inner\n    fn(*args)\n', '  File "/home/somnium/Desktop/CODE/Projects/CV/contador/scrapper/run.py", line 51, in single\n    return contador.read()\n', '  File "/home/somnium/Desktop/CODE/Projects/CV/contador/scrapper/contador.py", line 282, in read\n    succeed, values = _get_reading(user)\n', '  File "/home/somnium/Desktop/CODE/Projects/CV/contador/scrapper/contador.py", line 254, in _get_reading\n    driver = chrome_browser_setup()\n', '  File "/home/somnium/Desktop/CODE/Projects/CV/contador/scrapper/contador.py", line 163, in chrome_browser_setup\n    driver = Chrome(executable_path=PATH, options=opts)\n', '  File "/home/somnium/Desktop/CODE/Projects/CV/contador/venv/lib/python3.8/site-packages/selenium/webdriver/chrome/webdriver.py", line 76, in __init__\n    RemoteWebDriver.__init__(\n', '  File "/home/somnium/Desktop/CODE/Projects/CV/contador/venv/lib/python3.8/site-packages/selenium/webdriver/remote/webdriver.py", line 157, in __init__\n    self.start_session(capabilities, browser_profile)\n', '  File "/home/somnium/Desktop/CODE/Projects/CV/contador/venv/lib/python3.8/site-packages/selenium/webdriver/remote/webdriver.py", line 252, in start_session\n    response = self.execute(Command.NEW_SESSION, parameters)\n', '  File "/home/somnium/Desktop/CODE/Projects/CV/contador/venv/lib/python3.8/site-packages/selenium/webdriver/remote/webdriver.py", line 321, in execute\n    self.error_handler.check_response(response)\n', '  File "/home/somnium/Desktop/CODE/Projects/CV/contador/venv/lib/python3.8/site-packages/selenium/webdriver/remote/errorhandler.py", line 242, in check_response\n    raise exception_class(message, screen, stacktrace)\n', 'selenium.common.exceptions.WebDriverException: Message: Could not find default Chrome binary\n\n']
[ERROR] - ['Traceback (most recent call last):\n', '  File "/home/somnium/Desktop/CODE/Projects/CV/contador/scrapper/run.py", line 38, in _inner\n    fn(*args)\n', '  File "/home/somnium/Desktop/CODE/Projects/CV/contador/scrapper/run.py", line 51, in single\n    return contador.read()\n', '  File "/home/somnium/Desktop/CODE/Projects/CV/contador/scrapper/contador.py", line 282, in read\n    succeed, values = _get_reading(user)\n', '  File "/home/somnium/Desktop/CODE/Projects/CV/contador/scrapper/contador.py", line 254, in _get_reading\n    driver = chrome_browser_setup()\n', '  File "/home/somnium/Desktop/CODE/Projects/CV/contador/scrapper/contador.py", line 163, in chrome_browser_setup\n    driver = Chrome(executable_path=PATH, options=opts)\n', '  File "/home/somnium/Desktop/CODE/Projects/CV/contador/venv/lib/python3.8/site-packages/selenium/webdriver/chrome/webdriver.py", line 76, in __init__\n    RemoteWebDriver.__init__(\n', '  File "/home/somnium/Desktop/CODE/Projects/CV/contador/venv/lib/python3.8/site-packages/selenium/webdriver/remote/webdriver.py", line 157, in __init__\n    self.start_session(capabilities, browser_profile)\n', '  File "/home/somnium/Desktop/CODE/Projects/CV/contador/venv/lib/python3.8/site-packages/selenium/webdriver/remote/webdriver.py", line 252, in start_session\n    response = self.execute(Command.NEW_SESSION, parameters)\n', '  File "/home/somnium/Desktop/CODE/Projects/CV/contador/venv/lib/python3.8/site-packages/selenium/webdriver/remote/webdriver.py", line 321, in execute\n    self.error_handler.check_response(response)\n', '  File "/home/somnium/Desktop/CODE/Projects/CV/contador/venv/lib/python3.8/site-packages/selenium/webdriver/remote/errorhandler.py", line 242, in check_response\n    raise exception_class(message, screen, stacktrace)\n', 'selenium.common.exceptions.WebDriverException: Message: Could not find default Chrome binary\n\n']
[ERROR] - ['Traceback (most recent call last):\n', '  File "/home/somnium/Desktop/CODE/Projects/CV/contador/scrapper/run.py", line 38, in _inner\n    fn(*args)\n', '  File "/home/somnium/Desktop/CODE/Projects/CV/contador/scrapper/run.py", line 51, in single\n    return contador.read()\n', '  File "/home/somnium/Desktop/CODE/Projects/CV/contador/scrapper/contador.py", line 282, in read\n    succeed, values = _get_reading(user)\n', '  File "/home/somnium/Desktop/CODE/Projects/CV/contador/scrapper/contador.py", line 254, in _get_reading\n    driver = chrome_browser_setup()\n', '  File "/home/somnium/Desktop/CODE/Projects/CV/contador/scrapper/contador.py", line 163, in chrome_browser_setup\n    driver = Chrome(executable_path=PATH, options=opts)\n', '  File "/home/somnium/Desktop/CODE/Projects/CV/contador/venv/lib/python3.8/site-packages/selenium/webdriver/chrome/webdriver.py", line 76, in __init__\n    RemoteWebDriver.__init__(\n', '  File "/home/somnium/Desktop/CODE/Projects/CV/contador/venv/lib/python3.8/site-packages/selenium/webdriver/remote/webdriver.py", line 157, in __init__\n    self.start_session(capabilities, browser_profile)\n', '  File "/home/somnium/Desktop/CODE/Projects/CV/contador/venv/lib/python3.8/site-packages/selenium/webdriver/remote/webdriver.py", line 252, in start_session\n    response = self.execute(Command.NEW_SESSION, parameters)\n', '  File "/home/somnium/Desktop/CODE/Projects/CV/contador/venv/lib/python3.8/site-packages/selenium/webdriver/remote/webdriver.py", line 321, in execute\n    self.error_handler.check_response(response)\n', '  File "/home/somnium/Desktop/CODE/Projects/CV/contador/venv/lib/python3.8/site-packages/selenium/webdriver/remote/errorhandler.py", line 242, in check_response\n    raise exception_class(message, screen, stacktrace)\n', 'selenium.common.exceptions.WebDriverException: Message: Could not find default Chrome binary\n\n']
[ERROR] - ['Traceback (most recent call last):\n', '  File "/home/somnium/Desktop/CODE/Projects/CV/contador/scrapper/run.py", line 38, in _inner\n    fn(*args)\n', '  File "/home/somnium/Desktop/CODE/Projects/CV/contador/scrapper/run.py", line 51, in single\n    return contador.read()\n', '  File "/home/somnium/Desktop/CODE/Projects/CV/contador/scrapper/contador.py", line 282, in read\n    succeed, values = _get_reading(user)\n', '  File "/home/somnium/Desktop/CODE/Projects/CV/contador/scrapper/contador.py", line 254, in _get_reading\n    driver = chrome_browser_setup()\n', '  File "/home/somnium/Desktop/CODE/Projects/CV/contador/scrapper/contador.py", line 163, in chrome_browser_setup\n    driver = Chrome(executable_path=PATH, options=opts)\n', '  File "/home/somnium/Desktop/CODE/Projects/CV/contador/venv/lib/python3.8/site-packages/selenium/webdriver/chrome/webdriver.py", line 76, in __init__\n    RemoteWebDriver.__init__(\n', '  File "/home/somnium/Desktop/CODE/Projects/CV/contador/venv/lib/python3.8/site-packages/selenium/webdriver/remote/webdriver.py", line 157, in __init__\n    self.start_session(capabilities, browser_profile)\n', '  File "/home/somnium/Desktop/CODE/Projects/CV/contador/venv/lib/python3.8/site-packages/selenium/webdriver/remote/webdriver.py", line 252, in start_session\n    response = self.execute(Command.NEW_SESSION, parameters)\n', '  File "/home/somnium/Desktop/CODE/Projects/CV/contador/venv/lib/python3.8/site-packages/selenium/webdriver/remote/webdriver.py", line 321, in execute\n    self.error_handler.check_response(response)\n', '  File "/home/somnium/Desktop/CODE/Projects/CV/contador/venv/lib/python3.8/site-packages/selenium/webdriver/remote/errorhandler.py", line 242, in check_response\n    raise exception_class(message, screen, stacktrace)\n', 'selenium.common.exceptions.WebDriverException: Message: Could not find default Chrome binary\n\n']
