[ERROR] - ['Traceback (most recent call last):\n', '  File "/home/somnium/Desktop/CODE/Projects/CV/contador/scrapper/run.py", line 38, in _inner\n    fn(*args)\n', '  File "/home/somnium/Desktop/CODE/Projects/CV/contador/scrapper/run.py", line 51, in single\n    return contador.read()\n', '  File "/home/somnium/Desktop/CODE/Projects/CV/contador/scrapper/contador.py", line 248, in read\n    [\n', '  File "/home/somnium/Desktop/CODE/Projects/CV/contador/scrapper/contador.py", line 252, in <listcomp>\n    driver=browser_setup(),\n', '  File "/home/somnium/Desktop/CODE/Projects/CV/contador/scrapper/contador.py", line 96, in browser_setup\n    driver = Firefox(options=opts, executable_path=cfg["gecko_driver"])\n', '  File "/home/somnium/Desktop/CODE/Projects/CV/contador/venv/lib/python3.8/site-packages/selenium/webdriver/firefox/webdriver.py", line 164, in __init__\n    self.service.start()\n', '  File "/home/somnium/Desktop/CODE/Projects/CV/contador/venv/lib/python3.8/site-packages/selenium/webdriver/common/service.py", line 72, in start\n    self.process = subprocess.Popen(cmd, env=self.env,\n', '  File "/usr/lib/python3.8/subprocess.py", line 854, in __init__\n    self._execute_child(args, executable, preexec_fn, close_fds,\n', '  File "/usr/lib/python3.8/subprocess.py", line 1702, in _execute_child\n    raise child_exception_type(errno_num, err_msg, err_filename)\n', "OSError: [Errno 8] Exec format error: '/usr/local/bin/geckodriver'\n"]
[ERROR] - ['Traceback (most recent call last):\n', '  File "/home/somnium/Desktop/CODE/Projects/CV/contador/venv/lib/python3.8/site-packages/urllib3/connectionpool.py", line 670, in urlopen\n    httplib_response = self._make_request(\n', '  File "/home/somnium/Desktop/CODE/Projects/CV/contador/venv/lib/python3.8/site-packages/urllib3/connectionpool.py", line 426, in _make_request\n    six.raise_from(e, None)\n', '  File "<string>", line 3, in raise_from\n', '  File "/home/somnium/Desktop/CODE/Projects/CV/contador/venv/lib/python3.8/site-packages/urllib3/connectionpool.py", line 421, in _make_request\n    httplib_response = conn.getresponse()\n', '  File "/usr/lib/python3.8/http/client.py", line 1322, in getresponse\n    response.begin()\n', '  File "/usr/lib/python3.8/http/client.py", line 303, in begin\n    version, status, reason = self._read_status()\n', '  File "/usr/lib/python3.8/http/client.py", line 272, in _read_status\n    raise RemoteDisconnected("Remote end closed connection without"\n', 'http.client.RemoteDisconnected: Remote end closed connection without response\n', '\nDuring handling of the above exception, another exception occurred:\n\n', 'Traceback (most recent call last):\n', '  File "/home/somnium/Desktop/CODE/Projects/CV/contador/scrapper/run.py", line 38, in _inner\n    fn(*args)\n', '  File "/home/somnium/Desktop/CODE/Projects/CV/contador/scrapper/run.py", line 51, in single\n    return contador.read()\n', '  File "/home/somnium/Desktop/CODE/Projects/CV/contador/scrapper/contador.py", line 248, in read\n    [\n', '  File "/home/somnium/Desktop/CODE/Projects/CV/contador/scrapper/contador.py", line 252, in <listcomp>\n    driver=browser_setup(),\n', '  File "/home/somnium/Desktop/CODE/Projects/CV/contador/scrapper/contador.py", line 96, in browser_setup\n    driver = Firefox(options=opts, executable_path=cfg["gecko_driver"])\n', '  File "/home/somnium/Desktop/CODE/Projects/CV/contador/venv/lib/python3.8/site-packages/selenium/webdriver/firefox/webdriver.py", line 170, in __init__\n    RemoteWebDriver.__init__(\n', '  File "/home/somnium/Desktop/CODE/Projects/CV/contador/venv/lib/python3.8/site-packages/selenium/webdriver/remote/webdriver.py", line 157, in __init__\n    self.start_session(capabilities, browser_profile)\n', '  File "/home/somnium/Desktop/CODE/Projects/CV/contador/venv/lib/python3.8/site-packages/selenium/webdriver/remote/webdriver.py", line 252, in start_session\n    response = self.execute(Command.NEW_SESSION, parameters)\n', '  File "/home/somnium/Desktop/CODE/Projects/CV/contador/venv/lib/python3.8/site-packages/selenium/webdriver/remote/webdriver.py", line 319, in execute\n    response = self.command_executor.execute(driver_command, params)\n', '  File "/home/somnium/Desktop/CODE/Projects/CV/contador/venv/lib/python3.8/site-packages/selenium/webdriver/remote/remote_connection.py", line 374, in execute\n    return self._request(command_info[0], url, body=data)\n', '  File "/home/somnium/Desktop/CODE/Projects/CV/contador/venv/lib/python3.8/site-packages/selenium/webdriver/remote/remote_connection.py", line 397, in _request\n    resp = self._conn.request(method, url, body=body, headers=headers)\n', '  File "/home/somnium/Desktop/CODE/Projects/CV/contador/venv/lib/python3.8/site-packages/urllib3/request.py", line 79, in request\n    return self.request_encode_body(\n', '  File "/home/somnium/Desktop/CODE/Projects/CV/contador/venv/lib/python3.8/site-packages/urllib3/request.py", line 171, in request_encode_body\n    return self.urlopen(method, url, **extra_kw)\n', '  File "/home/somnium/Desktop/CODE/Projects/CV/contador/venv/lib/python3.8/site-packages/urllib3/poolmanager.py", line 336, in urlopen\n    response = conn.urlopen(method, u.request_uri, **kw)\n', '  File "/home/somnium/Desktop/CODE/Projects/CV/contador/venv/lib/python3.8/site-packages/urllib3/connectionpool.py", line 724, in urlopen\n    retries = retries.increment(\n', '  File "/home/somnium/Desktop/CODE/Projects/CV/contador/venv/lib/python3.8/site-packages/urllib3/util/retry.py", line 403, in increment\n    raise six.reraise(type(error), error, _stacktrace)\n', '  File "/home/somnium/Desktop/CODE/Projects/CV/contador/venv/lib/python3.8/site-packages/urllib3/packages/six.py", line 734, in reraise\n    raise value.with_traceback(tb)\n', '  File "/home/somnium/Desktop/CODE/Projects/CV/contador/venv/lib/python3.8/site-packages/urllib3/connectionpool.py", line 670, in urlopen\n    httplib_response = self._make_request(\n', '  File "/home/somnium/Desktop/CODE/Projects/CV/contador/venv/lib/python3.8/site-packages/urllib3/connectionpool.py", line 426, in _make_request\n    six.raise_from(e, None)\n', '  File "<string>", line 3, in raise_from\n', '  File "/home/somnium/Desktop/CODE/Projects/CV/contador/venv/lib/python3.8/site-packages/urllib3/connectionpool.py", line 421, in _make_request\n    httplib_response = conn.getresponse()\n', '  File "/usr/lib/python3.8/http/client.py", line 1322, in getresponse\n    response.begin()\n', '  File "/usr/lib/python3.8/http/client.py", line 303, in begin\n    version, status, reason = self._read_status()\n', '  File "/usr/lib/python3.8/http/client.py", line 272, in _read_status\n    raise RemoteDisconnected("Remote end closed connection without"\n', "urllib3.exceptions.ProtocolError: ('Connection aborted.', RemoteDisconnected('Remote end closed connection without response'))\n"]
[ERROR] - ['Traceback (most recent call last):\n', '  File "/home/somnium/Desktop/CODE/Projects/CV/contador/venv/lib/python3.8/site-packages/urllib3/connectionpool.py", line 670, in urlopen\n    httplib_response = self._make_request(\n', '  File "/home/somnium/Desktop/CODE/Projects/CV/contador/venv/lib/python3.8/site-packages/urllib3/connectionpool.py", line 426, in _make_request\n    six.raise_from(e, None)\n', '  File "<string>", line 3, in raise_from\n', '  File "/home/somnium/Desktop/CODE/Projects/CV/contador/venv/lib/python3.8/site-packages/urllib3/connectionpool.py", line 421, in _make_request\n    httplib_response = conn.getresponse()\n', '  File "/usr/lib/python3.8/http/client.py", line 1322, in getresponse\n    response.begin()\n', '  File "/usr/lib/python3.8/http/client.py", line 303, in begin\n    version, status, reason = self._read_status()\n', '  File "/usr/lib/python3.8/http/client.py", line 272, in _read_status\n    raise RemoteDisconnected("Remote end closed connection without"\n', 'http.client.RemoteDisconnected: Remote end closed connection without response\n', '\nDuring handling of the above exception, another exception occurred:\n\n', 'Traceback (most recent call last):\n', '  File "/home/somnium/Desktop/CODE/Projects/CV/contador/scrapper/run.py", line 38, in _inner\n    fn(*args)\n', '  File "/home/somnium/Desktop/CODE/Projects/CV/contador/scrapper/run.py", line 57, in multiple\n    return contador.read_multiple(pool)\n', '  File "/home/somnium/Desktop/CODE/Projects/CV/contador/scrapper/contador.py", line 269, in read_multiple\n    results = pool.map(_multiple, users)\n', '  File "/usr/lib/python3.8/multiprocessing/pool.py", line 364, in map\n    return self._map_async(func, iterable, mapstar, chunksize).get()\n', '  File "/usr/lib/python3.8/multiprocessing/pool.py", line 768, in get\n    raise self._value\n', '  File "/usr/lib/python3.8/multiprocessing/pool.py", line 125, in worker\n    result = (True, func(*args, **kwds))\n', '  File "/usr/lib/python3.8/multiprocessing/pool.py", line 48, in mapstar\n    return list(map(*args))\n', '  File "/home/somnium/Desktop/CODE/Projects/CV/contador/scrapper/contador.py", line 261, in _multiple\n    return ReadConsumption(\n', '  File "/home/somnium/Desktop/CODE/Projects/CV/contador/scrapper/contador.py", line 238, in get_reading\n    self.lectura()\n', '  File "/home/somnium/Desktop/CODE/Projects/CV/contador/scrapper/contador.py", line 217, in lectura\n    if self._read_succeed():\n', '  File "/home/somnium/Desktop/CODE/Projects/CV/contador/scrapper/contador.py", line 191, in _read_succeed\n    self.driver.find_element_by_css_selector(".percent")\n', '  File "/home/somnium/Desktop/CODE/Projects/CV/contador/venv/lib/python3.8/site-packages/selenium/webdriver/remote/webdriver.py", line 598, in find_element_by_css_selector\n    return self.find_element(by=By.CSS_SELECTOR, value=css_selector)\n', '  File "/home/somnium/Desktop/CODE/Projects/CV/contador/venv/lib/python3.8/site-packages/selenium/webdriver/remote/webdriver.py", line 976, in find_element\n    return self.execute(Command.FIND_ELEMENT, {\n', '  File "/home/somnium/Desktop/CODE/Projects/CV/contador/venv/lib/python3.8/site-packages/selenium/webdriver/remote/webdriver.py", line 319, in execute\n    response = self.command_executor.execute(driver_command, params)\n', '  File "/home/somnium/Desktop/CODE/Projects/CV/contador/venv/lib/python3.8/site-packages/selenium/webdriver/remote/remote_connection.py", line 374, in execute\n    return self._request(command_info[0], url, body=data)\n', '  File "/home/somnium/Desktop/CODE/Projects/CV/contador/venv/lib/python3.8/site-packages/selenium/webdriver/remote/remote_connection.py", line 397, in _request\n    resp = self._conn.request(method, url, body=body, headers=headers)\n', '  File "/home/somnium/Desktop/CODE/Projects/CV/contador/venv/lib/python3.8/site-packages/urllib3/request.py", line 79, in request\n    return self.request_encode_body(\n', '  File "/home/somnium/Desktop/CODE/Projects/CV/contador/venv/lib/python3.8/site-packages/urllib3/request.py", line 171, in request_encode_body\n    return self.urlopen(method, url, **extra_kw)\n', '  File "/home/somnium/Desktop/CODE/Projects/CV/contador/venv/lib/python3.8/site-packages/urllib3/poolmanager.py", line 336, in urlopen\n    response = conn.urlopen(method, u.request_uri, **kw)\n', '  File "/home/somnium/Desktop/CODE/Projects/CV/contador/venv/lib/python3.8/site-packages/urllib3/connectionpool.py", line 724, in urlopen\n    retries = retries.increment(\n', '  File "/home/somnium/Desktop/CODE/Projects/CV/contador/venv/lib/python3.8/site-packages/urllib3/util/retry.py", line 403, in increment\n    raise six.reraise(type(error), error, _stacktrace)\n', '  File "/home/somnium/Desktop/CODE/Projects/CV/contador/venv/lib/python3.8/site-packages/urllib3/packages/six.py", line 734, in reraise\n    raise value.with_traceback(tb)\n', '  File "/home/somnium/Desktop/CODE/Projects/CV/contador/venv/lib/python3.8/site-packages/urllib3/connectionpool.py", line 670, in urlopen\n    httplib_response = self._make_request(\n', '  File "/home/somnium/Desktop/CODE/Projects/CV/contador/venv/lib/python3.8/site-packages/urllib3/connectionpool.py", line 426, in _make_request\n    six.raise_from(e, None)\n', '  File "<string>", line 3, in raise_from\n', '  File "/home/somnium/Desktop/CODE/Projects/CV/contador/venv/lib/python3.8/site-packages/urllib3/connectionpool.py", line 421, in _make_request\n    httplib_response = conn.getresponse()\n', '  File "/usr/lib/python3.8/http/client.py", line 1322, in getresponse\n    response.begin()\n', '  File "/usr/lib/python3.8/http/client.py", line 303, in begin\n    version, status, reason = self._read_status()\n', '  File "/usr/lib/python3.8/http/client.py", line 272, in _read_status\n    raise RemoteDisconnected("Remote end closed connection without"\n', "urllib3.exceptions.ProtocolError: ('Connection aborted.', RemoteDisconnected('Remote end closed connection without response'))\n"]
